Workbook

Sheet Master
A1: UOP | B1: Comitente | C1: Descripción UOP | D1: Sub Rubro | E1: Cert Nro | F1: Concepto | G1: Concepto Agrupado | H1: Período | I1: Anticipo Desacopiado ($) | J1: Importe Certificado | K1: Importe a facturar | L1: Estado Validación por insp. | M1: Tipo | N1: N° Comprobante | O1: Fecha Factura | P1: Concepto / Descripción | Q1: Anulada | R1: NC | S1: Importe Neto Factura | T1: IVA 10,05 | U1: IVA 21% | V1: Perp IVA | W1: IIBB Bs As ($) | X1: IIBB CABA ($) | Y1: IIBB Tucuman($) | Z1: IIBB Sta Fe ($) | AA1: Importe de factura ($) | AB1: Fecha Pago 1 | AC1: Monto Pago 1 ($) | AD1: Fecha Pago 2 | AE1: Monto Pago 2 ($) | AF1: Fecha Pago 3+ | AG1: Monto Pago 3+ ($) | AH1: Ret ganancias | AI1: Total Cobrado ($) | AJ1: Saldo ($) | AK1: Demora Pago (días)
A2: 00-121 | B2: DEPOSITO SAN PEDRO Y TALLER CENTRAL | C2: DEPOSITO SAN PEDRO Y TALLER CENTRAL | D2: DEPOSITO SAN PEDRO Y TALLER CENTRAL | E2: NA | F2: NA | G2: NA | H2: NA | J2: 4365000 | K2: 4365000 | L2: Validado | M2: FC A | N2: 2566 | O2: 46038 | P2: Por el alquiler de 5 (cinco) días de excavadora con operador (Corresponde a U$S 3.000,00.- al tipo de cambio vendedor BN | Q2: NO | R2: N/A | S2: =+J2 | U2: =+S2*21% | V2: =+S2*3% | W2: =+S2*1.5% | X2: =IF(A2="00-175",S2*0.06,0) | AA2: =+S2+T2+U2+W2+X2+V2+Y2 | AB2: 46045 | AC2: 5216847 | AH2: 261228 | AI2: =+AC2+AE2+AG2+AH2 | AJ2: =+AA2-AI2 | AK2: =IF(Q2="ANULADA","N/A",IF(ABS(AJ2)>10,"Pendiente",IF(MAX(AB2,AD2,AF2)=0,"Pendiente",MAX(0,MAX(AB2,AD2,AF2)-O2))))
A3: 00-172 | B3: NUEVA MARINAS DE HUDSON INVERSORA SA | C3: Rotondas PN | D3: Rotondas PN | E3: 4 | F3: Cartificado Coste y Costas N4 | G3: Rotondas PN | H3: 45778 | J3: 23513374 | K3: 23513374 | L3: Validado | M3: FC A | N3: 2485 | O3: 45848 | P3: Cartificado Coste y Costas N4 | Q3: NO | R3: N/A | S3: =+J3 | U3: =+S3*21% | V3: =+S3*3% | W3: =+S3*2.5% | X3: =IF(A3="00-175",S3*0.06,0) | AA3: =+S3+T3+U3+W3+X3+V3+Y3 | AB3: 46219 | AC3: 29744418 | AI3: =+AC3+AE3+AG3+AH3 | AJ3: =+AA3-AI3 | AK3: =IF(Q3="ANULADA","N/A",IF(ABS(AJ3)>10,"Pendiente",IF(MAX(AB3,AD3,AF3)=0,"Pendiente",MAX(0,MAX(AB3,AD3,AF3)-O3))))
A4: 00-172 | B4: NUEVA MARINAS DE HUDSON INVERSORA SA | C4: Rotondas PN | D4: Rotondas PN | E4: 1 | F4: Certificado Nº 1 - May'25.. | G4: Rotondas PN | H4: 45778 | J4: 30876813 | K4: 30876813 | L4: Validado | M4: FC A | N4: 2486 | O4: 45848 | P4: Certificado Nº 1 - May'25.. | Q4: NO | R4: N/A | S4: =+J4 | U4: =+S4*21% | V4: =+S4*3% | W4: =+S4*2.5% | X4: =IF(A4="00-175",S4*0.06,0) | AA4: =+S4+T4+U4+W4+X4+V4+Y4 | AB4: 46219 | AC4: 39059169 | AI4: =+AC4+AE4+AG4+AH4 | AJ4: =+AA4-AI4 | AK4: =IF(Q4="ANULADA","N/A",IF(ABS(AJ4)>10,"Pendiente",IF(MAX(AB4,AD4,AF4)=0,"Pendiente",MAX(0,MAX(AB4,AD4,AF4)-O4))))
A5: 00-173 | B5: FIDEICOMISO MARINAS DEL PLATA | C5: EDIFICIOS MD 2 y 3 (Pto. NIZUC) | D5: Agua Tratada YPF | F5: Agua Tratada YPF | G5: Agua Tratada YPF | H5: NA | J5: 76100794 | K5: 76100794 | L5: Validado | M5: FC A | N5: 2483 | O5: 45833 | P5: Trabajos de Agua Tratada Planta YPF a Canal Exterior Puerto Nizuc. - EDIFICIOS MD 2 y 3 (Pto. NIZUC) (00173) | Q5: NO | R5: N/A | S5: =+J5 | U5: =+S5*21% | V5: =+S5*3% | W5: =+S5*2.5% | X5: =IF(A5="00-175",S5*0.06,0) | AA5: =+S5+T5+U5+W5+X5+V5+Y5 | AB5: 45839 | AC5: =AA5-AH5 | AH5: 2357473.6 | AI5: =+AC5+AE5+AG5+AH5 | AJ5: =+AA5-AI5 | AK5: =IF(Q5="ANULADA","N/A",IF(ABS(AJ5)>10,"Pendiente",IF(MAX(AB5,AD5,AF5)=0,"Pendiente",MAX(0,MAX(AB5,AD5,AF5)-O5))))
A6: 00-173 | B6: FIDEICOMISO MARINAS DEL PLATA | C6: EDIFICIOS MD 2 y 3 (Pto. NIZUC) | G6: Básico | H6: 45717 | J6: 1.5402088e+08 | K6: 1.5402088e+08 | M6: FC A | N6: 2517 | O6: 45946 | P6: Certificado Básico Nº 1 - Mar'25.. - EDIFICIOS MD 2 y 3 (Pto. NIZUC) (00173) | Q6: ANULADA | R6: 344 | S6: =+J6 | U6: =+S6*21% | V6: =+S6*3% | W6: =+S6*2.5% | X6: =IF(A6="00-175",S6*0.06,0) | AA6: =+S6+T6+U6+W6+X6+V6+Y6 | AI6: =+AC6+AE6+AG6+AH6 | AJ6: =+AA6-AI6 | AK6: =IF(Q6="ANULADA","N/A",IF(ABS(AJ6)>10,"Pendiente",IF(MAX(AB6,AD6,AF6)=0,"Pendiente",MAX(0,MAX(AB6,AD6,AF6)-O6))))
A7: 00-173 | B7: FIDEICOMISO MARINAS DEL PLATA | C7: EDIFICIOS MD 2 y 3 (Pto. NIZUC) | G7: Básico | H7: 45748 | J7: 87443208 | K7: 87443208 | M7: FC A | N7: 2518 | O7: 45946 | P7: Certificado Básico Nº 2 - Abr'25. - EDIFICIOS MD 2 y 3 (Pto. NIZUC) (00173) | Q7: ANULADA | R7: 345 | S7: =+J7 | U7: =+S7*21% | V7: =+S7*3% | W7: =+S7*2.5% | X7: =IF(A7="00-175",S7*0.06,0) | AA7: =+S7+T7+U7+W7+X7+V7+Y7 | AI7: =+AC7+AE7+AG7+AH7 | AJ7: =+AA7-AI7 | AK7: =IF(Q7="ANULADA","N/A",IF(ABS(AJ7)>10,"Pendiente",IF(MAX(AB7,AD7,AF7)=0,"Pendiente",MAX(0,MAX(AB7,AD7,AF7)-O7))))
A8: 00-173 | B8: FIDEICOMISO MARINAS DEL PLATA | C8: EDIFICIOS MD 2 y 3 (Pto. NIZUC) | G8: Básico | H8: 45778 | J8: 1.051615e+08 | K8: 1.051615e+08 | M8: FC A | N8: 2519 | O8: 45946 | P8: Certificado Básico Nº 3 - May'25.. - EDIFICIOS MD 2 y 3 (Pto. NIZUC) (00173) | Q8: ANULADA | R8: 346 | S8: =+J8 | U8: =+S8*21% | V8: =+S8*3% | W8: =+S8*2.5% | X8: =IF(A8="00-175",S8*0.06,0) | AA8: =+S8+T8+U8+W8+X8+V8+Y8 | AI8: =+AC8+AE8+AG8+AH8 | AJ8: =+AA8-AI8 | AK8: =IF(Q8="ANULADA","N/A",IF(ABS(AJ8)>10,"Pendiente",IF(MAX(AB8,AD8,AF8)=0,"Pendiente",MAX(0,MAX(AB8,AD8,AF8)-O8))))
A9: 00-173 | B9: FIDEICOMISO MARINAS DEL PLATA | C9: EDIFICIOS MD 2 y 3 (Pto. NIZUC) | G9: Básico | H9: 45809 | J9: 1.0509594e+08 | K9: 1.0509594e+08 | M9: FC A | N9: 2520 | O9: 45946 | P9: Certificado Básico Nº 4 - Jun'25. - EDIFICIOS MD 2 y 3 (Pto. NIZUC) (00173) | Q9: ANULADA | R9: 347 | S9: =+J9 | U9: =+S9*21% | V9: =+S9*3% | W9: =+S9*2.5% | X9: =IF(A9="00-175",S9*0.06,0) | AA9: =+S9+T9+U9+W9+X9+V9+Y9 | AI9: =+AC9+AE9+AG9+AH9 | AJ9: =+AA9-AI9 | AK9: =IF(Q9="ANULADA","N/A",IF(ABS(AJ9)>10,"Pendiente",IF(MAX(AB9,AD9,AF9)=0,"Pendiente",MAX(0,MAX(AB9,AD9,AF9)-O9))))
A10: 00-173 | B10: FIDEICOMISO MARINAS DEL PLATA | C10: EDIFICIOS MD 2 y 3 (Pto. NIZUC) | G10: Básico | H10: 45839 | J10: 1.0753981e+08 | K10: 1.0753981e+08 | M10: FC A | N10: 2521 | O10: 45946 | P10: Certificado Básico Nº 5 - Jul'25.. - EDIFICIOS MD 2 y 3 (Pto. NIZUC) (00173) | Q10: ANULADA | R10: 348 | S10: =+J10 | U10: =+S10*21% | V10: =+S10*3% | W10: =+S10*2.5% | X10: =IF(A10="00-175",S10*0.06,0) | AA10: =+S10+T10+U10+W10+X10+V10+Y10 | AI10: =+AC10+AE10+AG10+AH10 | AJ10: =+AA10-AI10 | AK10: =IF(Q10="ANULADA","N/A",IF(ABS(AJ10)>10,"Pendiente",IF(MAX(AB10,AD10,AF10)=0,"Pendiente",MAX(0,MAX(AB10,AD10,AF10)-O10))))
A11: 00-173 | B11: FIDEICOMISO MARINAS DEL PLATA | C11: EDIFICIOS MD 2 y 3 (Pto. NIZUC) | G11: Básico | H11: 45870 | J11: 1.0337725e+08 | K11: 1.0337725e+08 | M11: FC A | N11: 2522 | O11: 45946 | P11: Certificado Básico Nº 6 - Ago'25. - EDIFICIOS MD 2 y 3 (Pto. NIZUC) (00173) | Q11: ANULADA | R11: 349 | S11: =+J11 | U11: =+S11*21% | V11: =+S11*3% | W11: =+S11*2.5% | X11: =IF(A11="00-175",S11*0.06,0) | AA11: =+S11+T11+U11+W11+X11+V11+Y11 | AI11: =+AC11+AE11+AG11+AH11 | AJ11: =+AA11-AI11 | AK11: =IF(Q11="ANULADA","N/A",IF(ABS(AJ11)>10,"Pendiente",IF(MAX(AB11,AD11,AF11)=0,"Pendiente",MAX(0,MAX(AB11,AD11,AF11)-O11))))
A12: 00-173 | B12: FIDEICOMISO MARINAS DEL PLATA | C12: EDIFICIOS MD 2 y 3 (Pto. NIZUC) | G12: Redet. | H12: 45717 | J12: 26183550 | K12: 26183550 | M12: FC A | N12: 2523 | O12: 45946 | P12: Certificado Redeterminado Básico Nº 1 - Mar'25. - EDIFICIOS MD 2 y 3 (Pto. NIZUC) (00173) | Q12: ANULADA | R12: 350 | S12: =+J12 | U12: =+S12*21% | V12: =+S12*3% | W12: =+S12*2.5% | X12: =IF(A12="00-175",S12*0.06,0) | AA12: =+S12+T12+U12+W12+X12+V12+Y12 | AI12: =+AC12+AE12+AG12+AH12 | AJ12: =+AA12-AI12 | AK12: =IF(Q12="ANULADA","N/A",IF(ABS(AJ12)>10,"Pendiente",IF(MAX(AB12,AD12,AF12)=0,"Pendiente",MAX(0,MAX(AB12,AD12,AF12)-O12))))
A13: 00-173 | B13: FIDEICOMISO MARINAS DEL PLATA | C13: EDIFICIOS MD 2 y 3 (Pto. NIZUC) | G13: Redet. | H13: 45748 | J13: 17642182 | K13: 17642182 | M13: FC A | N13: 2524 | O13: 45946 | P13: Certificado Redeterminado Básico Nº 2 - Abr'25. - EDIFICIOS MD 2 y 3 (Pto. NIZUC) (00173) | Q13: ANULADA | R13: 351 | S13: =+J13 | U13: =+S13*21% | V13: =+S13*3% | W13: =+S13*2.5% | X13: =IF(A13="00-175",S13*0.06,0) | AA13: =+S13+T13+U13+W13+X13+V13+Y13 | AI13: =+AC13+AE13+AG13+AH13 | AJ13: =+AA13-AI13 | AK13: =IF(Q13="ANULADA","N/A",IF(ABS(AJ13)>10,"Pendiente",IF(MAX(AB13,AD13,AF13)=0,"Pendiente",MAX(0,MAX(AB13,AD13,AF13)-O13))))
A14: 00-173 | B14: FIDEICOMISO MARINAS DEL PLATA | C14: EDIFICIOS MD 2 y 3 (Pto. NIZUC) | G14: Redet. | H14: 45809 | J14: 29083534 | K14: 29083534 | M14: FC A | N14: 2525 | O14: 45946 | P14: Certificado Redeterminado Básico Nº 4 - Jun'25.. - EDIFICIOS MD 2 y 3 (Pto. NIZUC) (00173) | Q14: ANULADA | R14: 352 | S14: =+J14 | U14: =+S14*21% | V14: =+S14*3% | W14: =+S14*2.5% | X14: =IF(A14="00-175",S14*0.06,0) | AA14: =+S14+T14+U14+W14+X14+V14+Y14 | AI14: =+AC14+AE14+AG14+AH14 | AJ14: =+AA14-AI14 | AK14: =IF(Q14="ANULADA","N/A",IF(ABS(AJ14)>10,"Pendiente",IF(MAX(AB14,AD14,AF14)=0,"Pendiente",MAX(0,MAX(AB14,AD14,AF14)-O14))))
A15: 00-173 | B15: FIDEICOMISO MARINAS DEL PLATA | C15: EDIFICIOS MD 2 y 3 (Pto. NIZUC) | G15: Redet. | H15: 45778 | J15: 16929640 | K15: 16929640 | M15: FC A | N15: 2526 | O15: 45946 | P15: Certificado Redeterminado Básico Nº 3 - May'25.. - EDIFICIOS MD 2 y 3 (Pto. NIZUC) (00173) | Q15: ANULADA | R15: 353 | S15: =+J15 | U15: =+S15*21% | V15: =+S15*3% | W15: =+S15*2.5% | X15: =IF(A15="00-175",S15*0.06,0) | AA15: =+S15+T15+U15+W15+X15+V15+Y15 | AI15: =+AC15+AE15+AG15+AH15 | AJ15: =+AA15-AI15 | AK15: =IF(Q15="ANULADA","N/A",IF(ABS(AJ15)>10,"Pendiente",IF(MAX(AB15,AD15,AF15)=0,"Pendiente",MAX(0,MAX(AB15,AD15,AF15)-O15))))
A16: 00-173 | B16: FIDEICOMISO MARINAS DEL PLATA | C16: EDIFICIOS MD 2 y 3 (Pto. NIZUC) | G16: Redet. | H16: 45839 | J16: 26140242 | K16: 26140242 | M16: FC A | N16: 2527 | O16: 45946 | P16: Certificado Redeterminado Básico Nº 5 - Jul'25.. - EDIFICIOS MD 2 y 3 (Pto. NIZUC) (00173) | Q16: ANULADA | R16: 354 | S16: =+J16 | U16: =+S16*21% | V16: =+S16*3% | W16: =+S16*2.5% | X16: =IF(A16="00-175",S16*0.06,0) | AA16: =+S16+T16+U16+W16+X16+V16+Y16 | AI16: =+AC16+AE16+AG16+AH16 | AJ16: =+AA16-AI16 | AK16: =IF(Q16="ANULADA","N/A",IF(ABS(AJ16)>10,"Pendiente",IF(MAX(AB16,AD16,AF16)=0,"Pendiente",MAX(0,MAX(AB16,AD16,AF16)-O16))))
A17: 00-173 | B17: FIDEICOMISO MARINAS DEL PLATA | C17: EDIFICIOS MD 2 y 3 (Pto. NIZUC) | G17: Redet. | H17: 45870 | J17: 29337902 | K17: 29337902 | M17: FC A | N17: 2528 | O17: 45946 | P17: Certificado Redeterminado Básico Nº 6 - Ago'25.. - EDIFICIOS MD 2 y 3 (Pto. NIZUC) (00173) | Q17: ANULADA | R17: 355 | S17: =+J17 | U17: =+S17*21% | V17: =+S17*3% | W17: =+S17*2.5% | X17: =IF(A17="00-175",S17*0.06,0) | AA17: =+S17+T17+U17+W17+X17+V17+Y17 | AI17: =+AC17+AE17+AG17+AH17 | AJ17: =+AA17-AI17 | AK17: =IF(Q17="ANULADA","N/A",IF(ABS(AJ17)>10,"Pendiente",IF(MAX(AB17,AD17,AF17)=0,"Pendiente",MAX(0,MAX(AB17,AD17,AF17)-O17))))
... A23: 00-173 | B23: FIDEICOMISO MARINAS DEL PLATA | C23: EDIFICIOS MD 2 y 3 (Pto. NIZUC) | G23: Básico | H23: 45870 | J23: 1.9255204e+08 | K23: 1.9255204e+08 | M23: FC A | N23: 2534 | O23: 45946 | P23: Certificado Costes y Costas Nº 6 - Ago'25. - EDIFICIOS MD 2 y 3 (Pto. NIZUC) (00173) | Q23: ANULADA | R23: 361 | S23: =+J23 | U23: =+S23*21% | V23: =+S23*3% | W23: =+S23*2.5% | X23: =IF(A23="00-175",S23*0.06,0) | AA23: =+S23+T23+U23+W23+X23+V23+Y23 | AI23: =+AC23+AE23+AG23+AH23 | AJ23: =+AA23-AI23 | AK23: =IF(Q23="ANULADA","N/A",IF(ABS(AJ23)>10,"Pendiente",IF(MAX(AB23,AD23,AF23)=0,"Pendiente",MAX(0,MAX(AB23,AD23,AF23)-O23))))
A24: 00-175 | B24: NUEVA MARINAS DE HUDSON INVERSORA SA | C24: Laguna 4 - Puerto Nizuc | D24: Laguna 4 | E24: 1 | F24: Basico | G24: Básico | H24: 45778 | J24: 23489775 | K24: 23489775 | L24: Validado | M24: FC A | N24: 2488 | O24: 45848 | P24: Certificado Nº 1 - May'25.. - Laguna 4 - Puerto Nizuc (00175) | Q24: NO | R24: N/A | S24: =+J24 | U24: =+S24*21% | V24: =+S24*3% | W24: =+S24*0.3% | X24: =IF(A24="00-175",S24*0.06,0) | AA24: =+S24+T24+U24+W24+X24+V24+Y24 | AB24: 45861 | AC24: 30607177 | AI24: =+AC24+AE24+AG24+AH24 | AJ24: =+AA24-AI24 | AK24: =IF(Q24="ANULADA","N/A",IF(ABS(AJ24)>10,"Pendiente",IF(MAX(AB24,AD24,AF24)=0,"Pendiente",MAX(0,MAX(AB24,AD24,AF24)-O24))))
A25: 00-175 | B25: NUEVA MARINAS DE HUDSON INVERSORA SA | C25: Laguna 4 - Puerto Nizuc | D25: Laguna 4 | E25: 1 | F25: Basico | G25: Básico | H25: 45778 | J25: 86901861 | K25: 86901861 | L25: Validado | M25: FC A | N25: 2490 | O25: 45882 | P25: Certificado Nº 1 - May'25. - Laguna 4 - Puerto Nizuc (00175) | Q25: NO | R25: N/A | S25: =+J25 | U25: =+S25*21% | V25: =+S25*3% | W25: =+S25*0.3% | X25: =IF(A25="00-175",S25*0.06,0) | AA25: =+S25+T25+U25+W25+X25+V25+Y25 | AB25: 45909 | AC25: 1.1323312e+08 | AI25: =+AC25+AE25+AG25+AH25 | AJ25: =+AA25-AI25 | AK25: =IF(Q25="ANULADA","N/A",IF(ABS(AJ25)>10,"Pendiente",IF(MAX(AB25,AD25,AF25)=0,"Pendiente",MAX(0,MAX(AB25,AD25,AF25)-O25))))
A26: 00-175 | B26: NUEVA MARINAS DE HUDSON INVERSORA SA | C26: Laguna 4 - Puerto Nizuc | D26: Laguna 4 | E26: 1 | F26: Redet | G26: Redet. | H26: 45778 | J26: 4206050.1 | K26: 4206050.1 | L26: Validado | M26: FC A | N26: 2491 | O26: 45882 | P26: Certificado de Redeterminación Provisoria Nº 1 - May'25. - Laguna 4 - Puerto Nizuc (00175) | Q26: NO | R26: N/A | S26: =+J26 | U26: =+S26*21% | V26: =+S26*3% | W26: =+S26*0.3% | X26: =IF(A26="00-175",S26*0.06,0) | AA26: =+S26+T26+U26+W26+X26+V26+Y26 | AB26: 45909 | AC26: 5480483.2 | AI26: =+AC26+AE26+AG26+AH26 | AJ26: =+AA26-AI26 | AK26: =IF(Q26="ANULADA","N/A",IF(ABS(AJ26)>10,"Pendiente",IF(MAX(AB26,AD26,AF26)=0,"Pendiente",MAX(0,MAX(AB26,AD26,AF26)-O26))))
A27: 00-175 | B27: NUEVA MARINAS DE HUDSON INVERSORA SA | C27: Laguna 4 - Puerto Nizuc | D27: Laguna 4 | E27: 2 | F27: Basico | G27: Básico | H27: 45809 | J27: 85346702 | K27: 85346702 | L27: Validado | M27: FC A | N27: 2494 | O27: 45896 | P27: Certificado Nº 2 - Jun'25.. - Laguna 4 - Puerto Nizuc (00175) | Q27: NO | R27: N/A | S27: =+J27 | U27: =+S27*21% | V27: =+S27*3% | W27: =+S27*0.3% | X27: =IF(A27="00-175",S27*0.06,0) | AA27: =+S27+T27+U27+W27+X27+V27+Y27 | AB27: 45909 | AC27: 1.1120675e+08 | AI27: =+AC27+AE27+AG27+AH27 | AJ27: =+AA27-AI27 | AK27: =IF(Q27="ANULADA","N/A",IF(ABS(AJ27)>10,"Pendiente",IF(MAX(AB27,AD27,AF27)=0,"Pendiente",MAX(0,MAX(AB27,AD27,AF27)-O27))))
A28: 00-175 | B28: NUEVA MARINAS DE HUDSON INVERSORA SA | C28: Laguna 4 - Puerto Nizuc | D28: Laguna 4 | E28: 2 | F28: Redet | G28: Redet. | H28: 45809 | J28: 7110680.5 | K28: 7110680.5 | L28: Validado | M28: FC A | N28: 2495 | O28: 45896 | P28: Certificado de Redeterminación Provisoria Nº 2 - Jun'25. - Laguna 4 - Puerto Nizuc (00175) | Q28: NO | R28: N/A | S28: =+J28 | U28: =+S28*21% | V28: =+S28*3% | W28: =+S28*0.3% | X28: =IF(A28="00-175",S28*0.06,0) | AA28: =+S28+T28+U28+W28+X28+V28+Y28 | AB28: 45926 | AC28: 9265216.7 | AI28: =+AC28+AE28+AG28+AH28 | AJ28: =+AA28-AI28 | AK28: =IF(Q28="ANULADA","N/A",IF(ABS(AJ28)>10,"Pendiente",IF(MAX(AB28,AD28,AF28)=0,"Pendiente",MAX(0,MAX(AB28,AD28,AF28)-O28))))
A29: 00-175 | B29: NUEVA MARINAS DE HUDSON INVERSORA SA | C29: Laguna 4 - Puerto Nizuc | D29: Laguna 4 | E29: 2 | F29: Basico | G29: Básico | H29: 45809 | J29: 51931236 | K29: 51931236 | L29: Validado | M29: FC A | N29: 2499 | O29: 45897 | P29: Certificado Nº 2 - Jun'25.. - Laguna 4 - Puerto Nizuc (00175) | Q29: NO | R29: N/A | S29: =+J29 | U29: =+S29*21% | V29: =+S29*3% | W29: =+S29*0.3% | X29: =IF(A29="00-175",S29*0.06,0) | AA29: =+S29+T29+U29+W29+X29+V29+Y29 | AB29: 45917 | AC29: 67666400 | AI29: =+AC29+AE29+AG29+AH29 | AJ29: =+AA29-AI29 | AK29: =IF(Q29="ANULADA","N/A",IF(ABS(AJ29)>10,"Pendiente",IF(MAX(AB29,AD29,AF29)=0,"Pendiente",MAX(0,MAX(AB29,AD29,AF29)-O29))))
A30: 00-175 | B30: NUEVA MARINAS DE HUDSON INVERSORA SA | C30: Laguna 4 - Puerto Nizuc | D30: Laguna 4 | E30: 2 | F30: Redet | G30: Redet. | H30: 45809 | J30: 1244446.7 | K30: 1244446.7 | L30: Validado | M30: FC A | N30: 2500 | O30: 45897 | P30: Certificado de Redeterminación Provisoria Nº 2 - Jun'25. - Laguna 4 - Puerto Nizuc (00175) | Q30: NO | R30: N/A | S30: =+J30 | U30: =+S30*21% | V30: =+S30*3% | W30: =+S30*0.3% | X30: =IF(A30="00-175",S30*0.06,0) | AA30: =+S30+T30+U30+W30+X30+V30+Y30 | AB30: 45917 | AC30: 1621514 | AI30: =+AC30+AE30+AG30+AH30 | AJ30: =+AA30-AI30 | AK30: =IF(Q30="ANULADA","N/A",IF(ABS(AJ30)>10,"Pendiente",IF(MAX(AB30,AD30,AF30)=0,"Pendiente",MAX(0,MAX(AB30,AD30,AF30)-O30))))
A31: 00-175 | B31: NUEVA MARINAS DE HUDSON INVERSORA SA | C31: Laguna 4 - Puerto Nizuc | D31: Laguna 4 | E31: 3 | F31: Basico | G31: Básico | H31: 45839 | J31: 1.3022096e+08 | K31: 1.3022096e+08 | L31: Validado | M31: FC A | N31: 2504 | O31: 45903 | P31: Certificado Nº 3 - Jul'25.. - Laguna 4 - Puerto Nizuc (00175) | Q31: NO | R31: N/A | S31: =+J31 | U31: =+S31*21% | V31: =+S31*3% | W31: =+S31*0.3% | X31: =IF(A31="00-175",S31*0.06,0) | AA31: =+S31+T31+U31+W31+X31+V31+Y31 | AB31: 45926 | AC31: 1.6967792e+08 | AI31: =+AC31+AE31+AG31+AH31 | AJ31: =+AA31-AI31 | AK31: =IF(Q31="ANULADA","N/A",IF(ABS(AJ31)>10,"Pendiente",IF(MAX(AB31,AD31,AF31)=0,"Pendiente",MAX(0,MAX(AB31,AD31,AF31)-O31))))
A32: 00-175 | B32: NUEVA MARINAS DE HUDSON INVERSORA SA | C32: Laguna 4 - Puerto Nizuc | D32: Laguna 4 | E32: 3 | F32: Redet | G32: Redet. | H32: 45839 | J32: 10236945 | K32: 10236945 | L32: Validado | M32: FC A | N32: 2505 | O32: 45903 | P32: Certificado de Redeterminación Provisoria Nº 3 - Jul'25. - Laguna 4 - Puerto Nizuc (00175) | Q32: NO | R32: N/A | S32: =+J32 | U32: =+S32*21% | V32: =+S32*3% | W32: =+S32*0.3% | X32: =IF(A32="00-175",S32*0.06,0) | AA32: =+S32+T32+U32+W32+X32+V32+Y32 | AB32: 45926 | AC32: 13338740 | AI32: =+AC32+AE32+AG32+AH32 | AJ32: =+AA32-AI32 | AK32: =IF(Q32="ANULADA","N/A",IF(ABS(AJ32)>10,"Pendiente",IF(MAX(AB32,AD32,AF32)=0,"Pendiente",MAX(0,MAX(AB32,AD32,AF32)-O32))))
A33: 00-175 | B33: NUEVA MARINAS DE HUDSON INVERSORA SA | C33: Laguna 4 - Puerto Nizuc | D33: Laguna 4 | E33: 3 | F33: Basico | G33: Básico | H33: 45839 | J33: 11131246 | K33: 11131246 | L33: Validado | M33: FC A | N33: 2506 | O33: 45903 | P33: Certificado Nº 3 - Jul'25.. - Laguna 4 - Puerto Nizuc (00175) | Q33: NO | R33: N/A | S33: =+J33 | U33: =+S33*21% | V33: =+S33*3% | W33: =+S33*0.3% | X33: =IF(A33="00-175",S33*0.06,0) | AA33: =+S33+T33+U33+W33+X33+V33+Y33 | AB33: 45917 | AC33: 14504014 | AI33: =+AC33+AE33+AG33+AH33 | AJ33: =+AA33-AI33 | AK33: =IF(Q33="ANULADA","N/A",IF(ABS(AJ33)>10,"Pendiente",IF(MAX(AB33,AD33,AF33)=0,"Pendiente",MAX(0,MAX(AB33,AD33,AF33)-O33))))
A34: 00-175 | B34: NUEVA MARINAS DE HUDSON INVERSORA SA | C34: Laguna 4 - Puerto Nizuc | D34: Laguna 4 | E34: 3 | F34: Redet | G34: Redet. | H34: 45839 | J34: 656634.16 | K34: 656634.16 | L34: Validado | M34: FC A | N34: 2507 | O34: 45903 | P34: Certificado de Redeterminación Provisoria Nº 3 - Jul'25. - Laguna 4 - Puerto Nizuc (00175) | Q34: NO | R34: N/A | S34: =+J34 | U34: =+S34*21% | V34: =+S34*3% | W34: =+S34*0.3% | X34: =IF(A34="00-175",S34*0.06,0) | AA34: =+S34+T34+U34+W34+X34+V34+Y34 | AB34: 45917 | AC34: 855594.31 | AI34: =+AC34+AE34+AG34+AH34 | AJ34: =+AA34-AI34 | AK34: =IF(Q34="ANULADA","N/A",IF(ABS(AJ34)>10,"Pendiente",IF(MAX(AB34,AD34,AF34)=0,"Pendiente",MAX(0,MAX(AB34,AD34,AF34)-O34))))
A35: 00-175 | B35: NUEVA MARINAS DE HUDSON INVERSORA SA | C35: Laguna 4 - Puerto Nizuc | D35: Laguna 4 | E35: 4 | F35: Basico | G35: Básico | H35: 45870 | J35: 1.3151263e+08 | K35: 1.3151263e+08 | L35: Validado | M35: FC A | N35: 2509 | O35: 45915 | P35: Certificado Nº 4 - Ago'25. - Laguna 4 - Puerto Nizuc (00175) | Q35: NO | R35: N/A | S35: =+J35 | U35: =+S35*21% | V35: =+S35*3% | W35: =+S35*0.3% | X35: =IF(A35="00-175",S35*0.06,0) | AA35: =+S35+T35+U35+W35+X35+V35+Y35 | AB35: 45959 | AC35: 19283383 | AD35: 45987 | AE35: 1.5207758e+08 | AI35: =+AC35+AE35+AG35+AH35 | AJ35: =+AA35-AI35 | AK35: =IF(Q35="ANULADA","N/A",IF(ABS(AJ35)>10,"Pendiente",IF(MAX(AB35,AD35,AF35)=0,"Pendiente",MAX(0,MAX(AB35,AD35,AF35)-O35))))
A36: 00-175 | B36: NUEVA MARINAS DE HUDSON INVERSORA SA | C36: Laguna 4 - Puerto Nizuc | D36: Laguna 4 | E36: 4 | F36: Redet | G36: Redet. | H36: 45870 | J36: 14665290 | K36: 14665290 | L36: Validado | M36: FC A | N36: 2510 | O36: 45915 | P36: Certificado de Redeterminación Provisoria Nº 4 - Ago'25. - Laguna 4 - Puerto Nizuc (00175) | Q36: NO | R36: N/A | S36: =+J36 | U36: =+S36*21% | V36: =+S36*3% | W36: =+S36*0.3% | X36: =IF(A36="00-175",S36*0.06,0) | AA36: =+S36+T36+U36+W36+X36+V36+Y36 | AB36: 45987 | AC36: 19108873 | AI36: =+AC36+AE36+AG36+AH36 | AJ36: =+AA36-AI36 | AK36: =IF(Q36="ANULADA","N/A",IF(ABS(AJ36)>10,"Pendiente",IF(MAX(AB36,AD36,AF36)=0,"Pendiente",MAX(0,MAX(AB36,AD36,AF36)-O36))))
A37: 00-175 | B37: NUEVA MARINAS DE HUDSON INVERSORA SA | C37: Laguna 4 - Puerto Nizuc | D37: Laguna 4 | E37: 4 | F37: Basico | G37: Básico | H37: 45870 | J37: 10560323 | K37: 10560323 | L37: Validado | M37: FC A | N37: 2511 | O37: 45915 | P37: Certificado Nº 4 - Ago'25. - Laguna 4 - Puerto Nizuc (00175) | Q37: NO | R37: N/A | S37: =+J37 | U37: =+S37*21% | V37: =+S37*3% | W37: =+S37*0.3% | X37: =IF(A37="00-175",S37*0.06,0) | AA37: =+S37+T37+U37+W37+X37+V37+Y37 | AB37: 45939 | AC37: 13760101 | AI37: =+AC37+AE37+AG37+AH37 | AJ37: =+AA37-AI37 | AK37: =IF(Q37="ANULADA","N/A",IF(ABS(AJ37)>10,"Pendiente",IF(MAX(AB37,AD37,AF37)=0,"Pendiente",MAX(0,MAX(AB37,AD37,AF37)-O37))))
A38: 00-175 | B38: NUEVA MARINAS DE HUDSON INVERSORA SA | C38: Laguna 4 - Puerto Nizuc | D38: Laguna 4 | E38: 4 | F38: Redet | G38: Redet. | H38: 45870 | J38: 648234.33 | K38: 648234.33 | L38: Validado | M38: FC A | N38: 2512 | O38: 45915 | P38: Certificado de Redeterminación Provisoria Nº 4 - Ago'25. - Laguna 4 - Puerto Nizuc (00175) | Q38: NO | R38: N/A | S38: =+J38 | U38: =+S38*21% | V38: =+S38*3% | W38: =+S38*0.3% | X38: =IF(A38="00-175",S38*0.06,0) | AA38: =+S38+T38+U38+W38+X38+V38+Y38 | AB38: 45939 | AC38: 844649.33 | AI38: =+AC38+AE38+AG38+AH38 | AJ38: =+AA38-AI38 | AK38: =IF(Q38="ANULADA","N/A",IF(ABS(AJ38)>10,"Pendiente",IF(MAX(AB38,AD38,AF38)=0,"Pendiente",MAX(0,MAX(AB38,AD38,AF38)-O38))))
A39: 00-175 | B39: NUEVA MARINAS DE HUDSON INVERSORA SA | C39: Laguna 4 - Puerto Nizuc | D39: Laguna 4 | E39: 5 | F39: Basico | G39: Básico | H39: 45901 | J39: 9000058.1 | K39: 9000058.1 | L39: Validado | M39: FC A | N39: 2535 | O39: 45947 | P39: Certificado Nº 5 - Sep'25 - Ensanche. - Laguna 4 - Puerto Nizuc (00175) | Q39: NO | R39: N/A | S39: =+J39 | U39: =+S39*21% | V39: =+S39*3% | W39: =+S39*0.3% | X39: =IF(A39="00-175",S39*0.06,0) | AA39: =+S39+T39+U39+W39+X39+V39+Y39 | AB39: 45988 | AC39: 11727076 | AI39: =+AC39+AE39+AG39+AH39 | AJ39: =+AA39-AI39 | AK39: =IF(Q39="ANULADA","N/A",IF(ABS(AJ39)>10,"Pendiente",IF(MAX(AB39,AD39,AF39)=0,"Pendiente",MAX(0,MAX(AB39,AD39,AF39)-O39))))
A40: 00-175 | B40: NUEVA MARINAS DE HUDSON INVERSORA SA | C40: Laguna 4 - Puerto Nizuc | D40: Laguna 4 | E40: 5 | F40: Redet | G40: Redet. | H40: 45901 | J40: 379802.46 | K40: 379802.46 | L40: Validado | M40: FC A | N40: 2536 | O40: 45947 | P40: Certificado de Redeterminación Provisoria Nº 5 - Sep'25 - Ensanche. - Laguna 4 - Puerto Nizuc (00175) | Q40: NO | R40: N/A | S40: =+J40 | U40: =+S40*21% | V40: =+S40*3% | W40: =+S40*0.3% | X40: =IF(A40="00-175",S40*0.06,0) | AA40: =+S40+T40+U40+W40+X40+V40+Y40 | AB40: 45988 | AC40: 494882.6 | AI40: =+AC40+AE40+AG40+AH40 | AJ40: =+AA40-AI40 | AK40: =IF(Q40="ANULADA","N/A",IF(ABS(AJ40)>10,"Pendiente",IF(MAX(AB40,AD40,AF40)=0,"Pendiente",MAX(0,MAX(AB40,AD40,AF40)-O40))))
A41: 00-175 | B41: NUEVA MARINAS DE HUDSON INVERSORA SA | C41: Laguna 4 - Puerto Nizuc | D41: Laguna 4 | E41: 5 | F41: Basico | G41: Básico | H41: 45901 | J41: 1.8224181e+08 | K41: 1.8224181e+08 | L41: Validado | M41: FC A | N41: 2538 | O41: 45952 | P41: Certificado Nº 5 - Sep'25.. - Laguna 4 - Puerto Nizuc (00175) | Q41: NO | R41: N/A | S41: =+J41 | U41: =+S41*21% | V41: =+S41*3% | W41: =+S41*0.3% | X41: =IF(A41="00-175",S41*0.06,0) | AA41: =+S41+T41+U41+W41+X41+V41+Y41 | AB41: 45987 | AC41: 2.3746108e+08 | AI41: =+AC41+AE41+AG41+AH41 | AJ41: =+AA41-AI41 | AK41: =IF(Q41="ANULADA","N/A",IF(ABS(AJ41)>10,"Pendiente",IF(MAX(AB41,AD41,AF41)=0,"Pendiente",MAX(0,MAX(AB41,AD41,AF41)-O41))))
A42: 00-175 | B42: NUEVA MARINAS DE HUDSON INVERSORA SA | C42: Laguna 4 - Puerto Nizuc | D42: Laguna 4 | E42: 5 | F42: Redet | G42: Redet. | H42: 45901 | J42: 21925985 | K42: 21925985 | L42: Validado | M42: FC A | N42: 2539 | O42: 45952 | P42: Certificado de Redeterminación Provisoria Nº 5 - Sep'25. - Laguna 4 - Puerto Nizuc (00175) | Q42: NO | R42: N/A | S42: =+J42 | U42: =+S42*21% | V42: =+S42*3% | W42: =+S42*0.3% | X42: =IF(A42="00-175",S42*0.06,0) | AA42: =+S42+T42+U42+W42+X42+V42+Y42 | AB42: 45987 | AC42: 28384065 | AD42: 45973 | AE42: 185492.71 | AI42: =+AC42+AE42+AG42+AH42 | AJ42: =+AA42-AI42 | AK42: =IF(Q42="ANULADA","N/A",IF(ABS(AJ42)>10,"Pendiente",IF(MAX(AB42,AD42,AF42)=0,"Pendiente",MAX(0,MAX(AB42,AD42,AF42)-O42))))
A43: 00-175 | B43: NUEVA MARINAS DE HUDSON INVERSORA SA | C43: Laguna 4 - Puerto Nizuc | D43: Polder | E43: 5 | F43: Basico polder | G43: Básico | H43: 45901 | J43: 48541827 | K43: 48541827 | L43: Validado | M43: FC A | N43: 2540 | O43: 45953 | P43: Certificado Nº 1 - Sep'25. Camino del Polder. - Laguna 4 - Puerto Nizuc (00175) | Q43: NO | R43: N/A | S43: =+J43 | U43: =+S43*21% | V43: =+S43*3% | W43: =+S43*0.3% | X43: =IF(A43="00-175",S43*0.06,0) | AA43: =+S43+T43+U43+W43+X43+V43+Y43 | AB43: 45988 | AC43: 63250000 | AI43: =+AC43+AE43+AG43+AH43 | AJ43: =+AA43-AI43 | AK43: =IF(Q43="ANULADA","N/A",IF(ABS(AJ43)>10,"Pendiente",IF(MAX(AB43,AD43,AF43)=0,"Pendiente",MAX(0,MAX(AB43,AD43,AF43)-O43))))
A44: 00-175 | B44: NUEVA MARINAS DE HUDSON INVERSORA SA | C44: Laguna 4 - Puerto Nizuc | D44: Polder | E44: 5 | F44: Redet polder | G44: Redet. | H44: 45901 | J44: 3262010.7 | K44: 3262010.7 | L44: Validado | M44: FC A | N44: 2541 | O44: 45953 | P44: Certificado de Redeterminación Provisoria Nº 1 - Sep'25. - Laguna 4 - Puerto Nizuc (00175) | Q44: NO | R44: N/A | S44: =+J44 | U44: =+S44*21% | V44: =+S44*3% | W44: =+S44*0.3% | X44: =IF(A44="00-175",S44*0.06,0) | AA44: =+S44+T44+U44+W44+X44+V44+Y44 | AB44: 45988 | AC44: 4250400 | AI44: =+AC44+AE44+AG44+AH44 | AJ44: =+AA44-AI44 | AK44: =IF(Q44="ANULADA","N/A",IF(ABS(AJ44)>10,"Pendiente",IF(MAX(AB44,AD44,AF44)=0,"Pendiente",MAX(0,MAX(AB44,AD44,AF44)-O44))))
A45: 00-175 | B45: NUEVA MARINAS DE HUDSON INVERSORA SA | C45: Laguna 4 - Puerto Nizuc | D45: Laguna 4 | E45: 6 | F45: Basico | G45: Básico | H45: 45931 | J45: 2.4750722e+08 | K45: 2.4750722e+08 | L45: Validado | M45: FC A | N45: 2551 | O45: 45988 | P45: Certificado Basico Nº 6 - oct'25 - Laguna 4 - Puerto Nizuc (00175) | Q45: NO | R45: N/A | S45: =+J45 | U45: =+S45*21% | W45: =+S45*0.3% | X45: =IF(A45="00-175",S45*0.06,0) | AA45: =+S45+T45+U45+W45+X45+V45+Y45 | AB45: 46003 | AC45: 3.1507668e+08 | AI45: =+AC45+AE45+AG45+AH45 | AJ45: =+AA45-AI45 | AK45: =IF(Q45="ANULADA","N/A",IF(ABS(AJ45)>10,"Pendiente",IF(MAX(AB45,AD45,AF45)=0,"Pendiente",MAX(0,MAX(AB45,AD45,AF45)-O45))))
...

Sheet 530 con Mora - Calc de int
A1: CÁLCULO DE INTERESES POR MORA — Cláusulas 14.7 / 14.8 FIDIC
A2: Interés = Monto × (Tasa+3%) × (Días mora / 365)
A4: Fuente | B4: https://www.bna.com.ar/home/informacionalusuariofinanciero
A5: Tasa anual de interés (Cl. 14.8) | B5: 0.249 | C5: ← TNA - Tasa Nominal Anual Vencida con capitalización cada 30 días = T.N.A. (30 días)
A6: Plazo contractual de pago (días) | B6: 60 | C6: ← Días desde emisión de la factura
A7: Fecha de corte | B7: =TODAY()
A9: N° Factura | B9: Fecha Certificado | C9: Fecha Emisión Factura | D9: Plazo Contractual (días) | E9: Fecha Venc. de Pago | F9: Fecha Pago Efectivo | G9: Días de Mora | H9: Monto Certificado y facturado ($) | I9: Tasa Anual de Interés + 3% | J9: Interés por Mora ($) | K9: Monto Total a Pagar ($)
A10: 1998 | B10: 46035 | C10: 46035 | D10: =$B$6 | E10: =C10+D10 | F10: ="" | G10: =IF(F10="",MAX(0,$B$7-E10),MAX(0,F10-E10)) | H10: 50402511 | I10: =$B$5+3% | J10: =H10*I10*(G10/365) | K10: =H10+J10
A11: 1999 | B11: 46035 | C11: 46035 | D11: =$B$6 | E11: =C11+D11 | F11: ="" | G11: =IF(F11="",MAX(0,$B$7-E11),MAX(0,F11-E11)) | H11: 677271.96 | I11: =$B$5+3% | J11: =H11*I11*(G11/365) | K11: =H11+J11
A12: 2000 | B12: 46035 | C12: 46035 | D12: =$B$6 | E12: =C12+D12 | F12: ="" | G12: =IF(F12="",MAX(0,$B$7-E12),MAX(0,F12-E12)) | H12: 17699825 | I12: =$B$5+3% | J12: =H12*I12*(G12/365) | K12: =H12+J12
A13: 2001 | B13: 46035 | C13: 46035 | D13: =$B$6 | E13: =C13+D13 | F13: ="" | G13: =IF(F13="",MAX(0,$B$7-E13),MAX(0,F13-E13)) | H13: 1015907.9 | I13: =$B$5+3% | J13: =H13*I13*(G13/365) | K13: =H13+J13
A14: 2002 | B14: 46035 | C14: 46035 | D14: =$B$6 | E14: =C14+D14 | F14: ="" | G14: =IF(F14="",MAX(0,$B$7-E14),MAX(0,F14-E14)) | H14: 27253875 | I14: =$B$5+3% | J14: =H14*I14*(G14/365) | K14: =H14+J14
A15: 2003 | B15: 46035 | C15: 46035 | D15: =$B$6 | E15: =C15+D15 | F15: ="" | G15: =IF(F15="",MAX(0,$B$7-E15),MAX(0,F15-E15)) | H15: 1015907.9 | I15: =$B$5+3% | J15: =H15*I15*(G15/365) | K15: =H15+J15
A16: 2004 | B16: 46035 | C16: 46035 | D16: =$B$6 | E16: =C16+D16 | F16: ="" | G16: =IF(F16="",MAX(0,$B$7-E16),MAX(0,F16-E16)) | H16: 28627721 | I16: =$B$5+3% | J16: =H16*I16*(G16/365) | K16: =H16+J16
A17: 2005 | B17: 46035 | C17: 46035 | D17: =$B$6 | E17: =C17+D17 | F17: ="" | G17: =IF(F17="",MAX(0,$B$7-E17),MAX(0,F17-E17)) | H17: 238400.46 | I17: =$B$5+3% | J17: =H17*I17*(G17/365) | K17: =H17+J17
A18: 2006 | B18: 46035 | C18: 46035 | D18: =$B$6 | E18: =C18+D18 | F18: ="" | G18: =IF(F18="",MAX(0,$B$7-E18),MAX(0,F18-E18)) | H18: 6758414.6 | I18: =$B$5+3% | J18: =H18*I18*(G18/365) | K18: =H18+J18
A19: 2008 | B19: 46051 | C19: 46051 | D19: =$B$6 | E19: =C19+D19 | F19: ="" | G19: =IF(F19="",MAX(0,$B$7-E19),MAX(0,F19-E19)) | H19: 444448.23 | I19: =$B$5+3% | J19: =H19*I19*(G19/365) | K19: =H19+J19
A20: 2010 | B20: 46051 | C20: 46051 | D20: =$B$6 | E20: =C20+D20 | F20: ="" | G20: =IF(F20="",MAX(0,$B$7-E20),MAX(0,F20-E20)) | H20: 12832109 | I20: =$B$5+3% | J20: =H20*I20*(G20/365) | K20: =H20+J20
A21: 2011 | B21: 46056 | C21: 46056 | D21: =$B$6 | E21: =C21+D21 | F21: ="" | G21: =IF(F21="",MAX(0,$B$7-E21),MAX(0,F21-E21)) | H21: 184056.25 | I21: =$B$5+3% | J21: =H21*I21*(G21/365) | K21: =H21+J21
... A31: 2024 | B31: 46142 | C31: 46142 | D31: =$B$6 | E31: =C31+D31 | F31: ="" | G31: =IF(F31="",MAX(0,$B$7-E31),MAX(0,F31-E31)) | H31: 1.315933e+08 | I31: =$B$5+3% | J31: =H31*I31*(G31/365) | K31: =H31+J31
A32: TOTAL | G32: =IF(COUNTA(F10:F31)>0,AVERAGE(G10:G31),AVERAGE(G10:G31)) | H32: =SUBTOTAL(109,H10:H31) | J32: =SUBTOTAL(109,J10:J31) | K32: =SUBTOTAL(109,K10:K31)
A34: RESUMEN
A35: Total Monto Certificados | B35: =H32
A36: Total Interés por Mora (Cl. 14.8) | B36: =J32
A37: Total a Reclamar | B37: =B35+B36
A38: Certificados en mora | B38: =COUNTIF(G10:G31,">"&0)
A39: Demora promedio (días) | B39: =G32

Sheet Anticipos
A1: UOP | B1: Descripción UOP | C1: Tipo Anticipo | D1: Nro Anticipo | E1: Factura | F1: Fecha Desembolso | G1: Monto Original ($) | H1: Con actualizacion | I1: Total Desacopiado ($) | J1: Saldo Pendiente ($) | K1: % Desacopiado
A2: 00-181 | B2: Bombeo Planta Potabilizadora Puerto Nizuc | C2: Anticipo Financiero 1 | D2: 1 | E2: 0018-00002514 | F2: 45938 | G2: 21615296 | I2: =SUMIFS(Master!I:I,Master!D:D,"Provision Tableros electricos") | J2: =G2-I2 | K2: =IFERROR(I2/G2,0)
A3: 00-181 | B3: Bombeo Planta Potabilizadora Puerto Nizuc | C3: Anticipo Cableado | D3: 2 | E3: 0018-00002548 | F3: 46078 | G3: 48893832 | I3: =SUMIFS(Master!I:I,Master!D:D,"Conexión y Cableado") | J3: =G3-I3 | K3: =IFERROR(I3/G3,0)
A4: 00-181 | B4: Bombeo Planta Potabilizadora Puerto Nizuc | C4: Anticipo Manifold y tableros | D4: 3 | E4: 0018-00002498 | F4: 45904 | G4: 81685880 | I4: =SUMIFS(Master!I:I,Master!D:D,"Manifold y Tableros") | J4: =G4-I4 | K4: =IFERROR(I4/G4,0)
A5: 00-181 | B5: Bombeo Planta Potabilizadora Puerto Nizuc | C5: Anticipo Bombeo Planta | D5: 4 | E5: 0018-00002503 | F5: 45916 | G5: 12601653 | I5: =SUMIFS(Master!I:I,Master!D:D,"Oficina Tecnica") | J5: =G5-I5 | K5: =IFERROR(I5/G5,0)
A6: 00-530 | B6: Redes y Colectores Cloacales Alderetes - Tucumán | C6: Anticipo Financiero | D6: 1 | E6: 0018-00001365 | F6: 44308 | G6: 1.7596957e+08 | I6: =SUMIFS(Master!I:I,Master!A:A,A6) | J6: =G6-I6 | K6: =IFERROR(I6/G6,0)
A7: 00-178 | B7: Edificio Oficinas - Puerto Nizuc | C7: Anticipo Financiero | D7: 1 | E7: 0018-00002555 | F7: 46007 | G7: 3.3906773e+09 | H7: =+G7*1.044428 | I7: =SUMIFS(Master!I:I,Master!A:A,A7) | J7: =H7-I7 | K7: =IFERROR(I7/H7,0)
A8: 00-177 | B8: Edificios 7 y 8 - Puerto Nizuc | C8: Anticipo Financiero | D8: 1 | E8: 0018-00002546 | F8: 46007 | G8: 4.8370062e+09 | H8: =+I8 | I8: =SUMIFS(Master!I:I,Master!A:A,A8) | J8: =H8-I8 | K8: =IFERROR(I8/H8,0)

Sheet Montos contractuales
A2: UOP | B2: Concepto | C2: Monto | D2: Fecha
A3: 00-530 | B3: contrato Ajuste alzado | C3: 1.7596957e+09 | D3: 44256
A4: 00-530 | B4: Ampliacion | C4: 3.5193462e+08 | D4: 46042
A5: 00-175 | B5: Carta Oferta | C5: 2.3370562e+09 | D5: 45870
A6: 00-176 | B6: Carta Oferta | C6: 5000000000 | D6: 46113
A7: 00-177 | B7: Contrato Coste y Costas | C7: 3.0896494e+10 | D7: 45870
A8: 00-178 | B8: Contrato Coste y Costas | C8: 3.3906773e+10 | D8: 45870
A9: 00-636 | B9: Carta Oferta | C9: 1500000000 | D9: 45839
